<?xml version="1.0"?>
<robot xmlns:xacro="http://www.ros.org/wiki/xacro" name="roomba">

    <xacro:include filename="inertial_macros.xacro"/>

    <link name="base_link"></link>

    <link name="roomba/lidar/gpu_lidar">
        <visual>
            <geometry>
                <cylinder length="0.04" radius="0.07" />
            </geometry>
            <origin rpy="0 0 0" xyz="0 0 0"/>
        </visual>
        <collision>
            <geometry>
                <cylinder length="0.04" radius="0.07" />
            </geometry>
        </collision>
        <xacro:inertial_cylinder mass="1" length="0.04" radius="0.07">
            <origin xyz="0 0 0" rpy="0 0 0"/>
        </xacro:inertial_cylinder>
    </link>

    <link name="roomba/lidar/camera"></link>

    <link name="chassis">
        <visual>
            <geometry>
                <box size="0.6 0.4 0.1"/>
            </geometry>
            <origin rpy="0 0 0" xyz="-0.2 0 -0.065"/>
        </visual>
        <collision>
            <geometry>
                <box size="0.6 0.4 0.1"/>
            </geometry>
        </collision>
        <xacro:inertial_box mass="30" x="0.6" y="0.4" z="0.1">
            <origin xyz="0 0 0" rpy="0 0 0"/>
        </xacro:inertial_box>
    </link>

    <link name="left_wheel">
        <visual>
            <geometry>
                <cylinder radius="0.1" length="0.04"/>
            </geometry>
        </visual>
        <collision>
            <geometry>
                <cylinder radius="0.1" length="0.04"/>
            </geometry>
        </collision>
        <xacro:inertial_cylinder mass="1" length="0.04" radius="0.1">
            <origin xyz="0 0 0" rpy="0 0 0"/>
        </xacro:inertial_cylinder>
    </link>

    <link name="right_wheel">
        <visual>
            <geometry>
                <cylinder radius="0.1" length="0.04"/>
            </geometry>
        </visual>
        <collision>
            <geometry>
                <cylinder radius="0.1" length="0.04"/>
            </geometry>
        </collision>
        <xacro:inertial_cylinder mass="1" length="0.04" radius="0.1">
            <origin xyz="0 0 0" rpy="0 0 0"/>
        </xacro:inertial_cylinder>
    </link>

    <link name="caster_wheel">
        <visual>
            <geometry>
                <sphere radius="0.05"/>
            </geometry>
            <origin rpy="0 0 0" xyz="0 0 -0.115"/>
        </visual>
        <collision>
            <geometry>
                <sphere radius="0.05"/>
            </geometry>
        </collision>
        <xacro:inertial_sphere mass="1" radius="0.05">
            <origin xyz="0 0 0" rpy="0 0 0"/>
        </xacro:inertial_sphere>
    </link>
    
    <joint name="base_joint" type="fixed">
        <parent link="base_link"/>
        <child link="roomba/lidar/gpu_lidar"/>
    </joint>

    <joint name="lidar_joint" type="fixed">
        <parent link="roomba/lidar/gpu_lidar"/>
        <child link="chassis"/>
        <origin xyz="0 0 0"/>
    </joint>

    <joint name="camera_joint" type="fixed">
        <parent link="roomba/lidar/gpu_lidar"/>
        <child link="roomba/lidar/camera"/>
        <origin xyz="0 0 0"/>
    </joint>

    <joint name="left_wheel_joint" type="continuous">
        <parent link="chassis"/>
        <child link="left_wheel"/>
        <origin xyz="-0.35 0.22 -0.065" rpy="-1.5707 0 0"/>
        <axis xyz="0 0 1"/>
    </joint>

    <joint name="right_wheel_joint" type="continuous">
        <parent link="chassis"/>
        <child link="right_wheel"/>
        <origin xyz="-0.35 -0.22 -0.065" rpy="1.5707 0 0"/>
        <axis xyz="0 0 -1"/>
    </joint>

    <joint name="caster_wheel_joint" type="fixed">
        <parent link="chassis"/>
        <child link="caster_wheel"/>
    </joint>
    
</robot>
